2023-06-15 03:38:18,554 - INFO - Application started
2023-06-15 03:38:21,903 - INFO - Application is stopping. This might take a moment.
2023-06-15 03:38:21,903 - INFO - Application.stop() complete
2023-06-15 03:39:07,056 - INFO - Start bot
2023-06-15 03:39:07,752 - INFO - Application started
2023-06-15 03:39:25,174 - INFO - Application is stopping. This might take a moment.
2023-06-15 03:39:25,174 - INFO - Application.stop() complete
2023-06-15 03:42:20,343 - INFO - Start bot - msg
2023-06-15 03:42:21,060 - INFO - Application started - msg
2023-06-15 03:42:27,766 - INFO - Application is stopping. This might take a moment. - msg
2023-06-15 03:42:27,767 - INFO - Application.stop() complete - msg
2023-06-16 07:30:33,515 - INFO - Start bot - msg
2023-06-16 07:30:34,193 - INFO - Application started - msg
2023-06-16 07:30:55,081 - ERROR - No error handlers are registered, logging exception. - msg
Traceback (most recent call last):
  File "C:\Users\M9X\AppData\Local\Programs\Python\Python39\lib\site-packages\telegram\ext\_application.py", line 1124, in process_update
    await coroutine
  File "C:\Users\M9X\AppData\Local\Programs\Python\Python39\lib\site-packages\telegram\ext\_handler.py", line 141, in handle_update
    return await self.callback(update, context)
  File "C:\Users\M9X\Desktop\4_Сем\ИС_Python\Sem4_is\9_Async_ChatBots\Task_6.py", line 79, in back
    log(update.effective_chat.id, '/back')
  File "C:\Users\M9X\Desktop\4_Сем\ИС_Python\Sem4_is\9_Async_ChatBots\Task_5.py", line 6, in log
    with open(f'C:\logs\{user_id}.log', 'a+') as file:
FileNotFoundError: [Errno 2] No such file or directory: 'C:\\logs\\438155452.log'
2023-06-16 07:30:57,629 - ERROR - No error handlers are registered, logging exception. - msg
Traceback (most recent call last):
  File "C:\Users\M9X\AppData\Local\Programs\Python\Python39\lib\site-packages\telegram\ext\_application.py", line 1124, in process_update
    await coroutine
  File "C:\Users\M9X\AppData\Local\Programs\Python\Python39\lib\site-packages\telegram\ext\_handler.py", line 141, in handle_update
    return await self.callback(update, context)
  File "C:\Users\M9X\Desktop\4_Сем\ИС_Python\Sem4_is\9_Async_ChatBots\Task_6.py", line 146, in version
    log(update.effective_chat.id, '/version')
  File "C:\Users\M9X\Desktop\4_Сем\ИС_Python\Sem4_is\9_Async_ChatBots\Task_5.py", line 6, in log
    with open(f'C:\logs\{user_id}.log', 'a+') as file:
FileNotFoundError: [Errno 2] No such file or directory: 'C:\\logs\\438155452.log'
2023-06-16 07:30:59,209 - ERROR - No error handlers are registered, logging exception. - msg
Traceback (most recent call last):
  File "C:\Users\M9X\AppData\Local\Programs\Python\Python39\lib\site-packages\telegram\ext\_application.py", line 1124, in process_update
    await coroutine
  File "C:\Users\M9X\AppData\Local\Programs\Python\Python39\lib\site-packages\telegram\ext\_handler.py", line 141, in handle_update
    return await self.callback(update, context)
  File "C:\Users\M9X\Desktop\4_Сем\ИС_Python\Sem4_is\9_Async_ChatBots\Task_6.py", line 162, in weather
    log(update.effective_chat.id, '/weather')
  File "C:\Users\M9X\Desktop\4_Сем\ИС_Python\Sem4_is\9_Async_ChatBots\Task_5.py", line 6, in log
    with open(f'C:\logs\{user_id}.log', 'a+') as file:
FileNotFoundError: [Errno 2] No such file or directory: 'C:\\logs\\438155452.log'
2023-06-16 07:31:36,637 - INFO - Application is stopping. This might take a moment. - msg
2023-06-16 07:31:36,637 - INFO - Application.stop() complete - msg
2023-06-16 07:32:28,425 - INFO - Start bot - msg
2023-06-16 07:32:29,037 - INFO - Application started - msg
2023-06-16 07:32:46,090 - INFO - Application is stopping. This might take a moment. - msg
2023-06-16 07:32:46,090 - INFO - Application.stop() complete - msg
2023-06-16 07:33:07,224 - INFO - Start bot - msg
2023-06-16 07:33:07,874 - INFO - Application started - msg
2023-06-16 07:33:29,527 - INFO - Application is stopping. This might take a moment. - msg
2023-06-16 07:33:29,527 - INFO - Application.stop() complete - msg
2023-06-16 07:37:39,128 - INFO - Start bot - msg
2023-06-16 07:37:39,833 - INFO - Application started - msg
2023-06-16 07:40:53,052 - INFO - Application is stopping. This might take a moment. - msg
2023-06-16 07:40:53,052 - INFO - Application.stop() complete - msg
2023-06-16 07:40:55,946 - INFO - Start bot - msg
2023-06-16 07:40:56,521 - INFO - Application started - msg
2023-06-16 07:41:39,862 - ERROR - No error handlers are registered, logging exception. - msg
Traceback (most recent call last):
  File "C:\Users\M9X\AppData\Local\Programs\Python\Python39\lib\site-packages\urllib3\connection.py", line 200, in _new_conn
    sock = connection.create_connection(
  File "C:\Users\M9X\AppData\Local\Programs\Python\Python39\lib\site-packages\urllib3\util\connection.py", line 85, in create_connection
    raise err
  File "C:\Users\M9X\AppData\Local\Programs\Python\Python39\lib\site-packages\urllib3\util\connection.py", line 73, in create_connection
    sock.connect(sa)
TimeoutError: [WinError 10060] Попытка установить соединение была безуспешной, т.к. от другого компьютера за требуемое время не получен нужный отклик, или было разорвано уже установленное соединение из-за неверного отклика уже подключенного компьютера

The above exception was the direct cause of the following exception:

Traceback (most recent call last):
  File "C:\Users\M9X\AppData\Local\Programs\Python\Python39\lib\site-packages\urllib3\connectionpool.py", line 790, in urlopen
    response = self._make_request(
  File "C:\Users\M9X\AppData\Local\Programs\Python\Python39\lib\site-packages\urllib3\connectionpool.py", line 491, in _make_request
    raise new_e
  File "C:\Users\M9X\AppData\Local\Programs\Python\Python39\lib\site-packages\urllib3\connectionpool.py", line 467, in _make_request
    self._validate_conn(conn)
  File "C:\Users\M9X\AppData\Local\Programs\Python\Python39\lib\site-packages\urllib3\connectionpool.py", line 1092, in _validate_conn
    conn.connect()
  File "C:\Users\M9X\AppData\Local\Programs\Python\Python39\lib\site-packages\urllib3\connection.py", line 604, in connect
    self.sock = sock = self._new_conn()
  File "C:\Users\M9X\AppData\Local\Programs\Python\Python39\lib\site-packages\urllib3\connection.py", line 215, in _new_conn
    raise NewConnectionError(
urllib3.exceptions.NewConnectionError: <urllib3.connection.HTTPSConnection object at 0x00000152B9002400>: Failed to establish a new connection: [WinError 10060] Попытка установить соединение была безуспешной, т.к. от другого компьютера за требуемое время не получен нужный отклик, или было разорвано уже установленное соединение из-за неверного отклика уже подключенного компьютера

The above exception was the direct cause of the following exception:

Traceback (most recent call last):
  File "C:\Users\M9X\AppData\Local\Programs\Python\Python39\lib\site-packages\requests\adapters.py", line 486, in send
    resp = conn.urlopen(
  File "C:\Users\M9X\AppData\Local\Programs\Python\Python39\lib\site-packages\urllib3\connectionpool.py", line 844, in urlopen
    retries = retries.increment(
  File "C:\Users\M9X\AppData\Local\Programs\Python\Python39\lib\site-packages\urllib3\util\retry.py", line 515, in increment
    raise MaxRetryError(_pool, url, reason) from reason  # type: ignore[arg-type]
urllib3.exceptions.MaxRetryError: HTTPSConnectionPool(host='teletype.in', port=443): Max retries exceeded with url: /@haskie1337 (Caused by NewConnectionError('<urllib3.connection.HTTPSConnection object at 0x00000152B9002400>: Failed to establish a new connection: [WinError 10060] Попытка установить соединение была безуспешной, т.к. от другого компьютера за требуемое время не получен нужный отклик, или было разорвано уже установленное соединение из-за неверного отклика уже подключенного компьютера'))

During handling of the above exception, another exception occurred:

Traceback (most recent call last):
  File "C:\Users\M9X\AppData\Local\Programs\Python\Python39\lib\site-packages\telegram\ext\_application.py", line 1124, in process_update
    await coroutine
  File "C:\Users\M9X\AppData\Local\Programs\Python\Python39\lib\site-packages\telegram\ext\_handler.py", line 141, in handle_update
    return await self.callback(update, context)
  File "C:\Users\M9X\Desktop\4_Сем\ИС_Python\Sem4_is\9_Async_ChatBots\Task_6.py", line 106, in lastwork
    r = requests.get('https://teletype.in/@haskie1337')
  File "C:\Users\M9X\AppData\Local\Programs\Python\Python39\lib\site-packages\requests\api.py", line 73, in get
    return request("get", url, params=params, **kwargs)
  File "C:\Users\M9X\AppData\Local\Programs\Python\Python39\lib\site-packages\requests\api.py", line 59, in request
    return session.request(method=method, url=url, **kwargs)
  File "C:\Users\M9X\AppData\Local\Programs\Python\Python39\lib\site-packages\requests\sessions.py", line 589, in request
    resp = self.send(prep, **send_kwargs)
  File "C:\Users\M9X\AppData\Local\Programs\Python\Python39\lib\site-packages\requests\sessions.py", line 703, in send
    r = adapter.send(request, **kwargs)
  File "C:\Users\M9X\AppData\Local\Programs\Python\Python39\lib\site-packages\requests\adapters.py", line 519, in send
    raise ConnectionError(e, request=request)
requests.exceptions.ConnectionError: HTTPSConnectionPool(host='teletype.in', port=443): Max retries exceeded with url: /@haskie1337 (Caused by NewConnectionError('<urllib3.connection.HTTPSConnection object at 0x00000152B9002400>: Failed to establish a new connection: [WinError 10060] Попытка установить соединение была безуспешной, т.к. от другого компьютера за требуемое время не получен нужный отклик, или было разорвано уже установленное соединение из-за неверного отклика уже подключенного компьютера'))
2023-06-16 07:41:51,631 - INFO - Application is stopping. This might take a moment. - msg
2023-06-16 07:41:51,631 - INFO - Application.stop() complete - msg
2023-06-16 07:48:38,339 - INFO - Start bot - msg
2023-06-16 07:48:39,364 - INFO - Application started - msg
2023-06-16 07:51:40,896 - ERROR - Error while getting Updates: httpx.ConnectError: All connection attempts failed - msg
2023-06-16 07:51:40,896 - ERROR - No error handlers are registered, logging exception. - msg
Traceback (most recent call last):
  File "C:\Users\M9X\AppData\Local\Programs\Python\Python39\lib\site-packages\anyio\_core\_sockets.py", line 164, in try_connect
    stream = await asynclib.connect_tcp(remote_host, remote_port, local_address)
  File "C:\Users\M9X\AppData\Local\Programs\Python\Python39\lib\site-packages\anyio\_backends\_asyncio.py", line 1691, in connect_tcp
    await get_running_loop().create_connection(
  File "C:\Users\M9X\AppData\Local\Programs\Python\Python39\lib\asyncio\base_events.py", line 1056, in create_connection
    raise exceptions[0]
  File "C:\Users\M9X\AppData\Local\Programs\Python\Python39\lib\asyncio\base_events.py", line 1041, in create_connection
    sock = await self._connect_sock(
  File "C:\Users\M9X\AppData\Local\Programs\Python\Python39\lib\asyncio\base_events.py", line 955, in _connect_sock
    await self.sock_connect(sock, address)
  File "C:\Users\M9X\AppData\Local\Programs\Python\Python39\lib\asyncio\proactor_events.py", line 702, in sock_connect
    return await self._proactor.connect(sock, address)
  File "C:\Users\M9X\AppData\Local\Programs\Python\Python39\lib\asyncio\windows_events.py", line 812, in _poll
    value = callback(transferred, key, ov)
  File "C:\Users\M9X\AppData\Local\Programs\Python\Python39\lib\asyncio\windows_events.py", line 599, in finish_connect
    ov.getresult()
ConnectionAbortedError: [WinError 1236] Подключение к сети было разорвано локальной системой

The above exception was the direct cause of the following exception:

Traceback (most recent call last):
  File "C:\Users\M9X\AppData\Local\Programs\Python\Python39\lib\site-packages\httpcore\_exceptions.py", line 10, in map_exceptions
    yield
  File "C:\Users\M9X\AppData\Local\Programs\Python\Python39\lib\site-packages\httpcore\backends\asyncio.py", line 111, in connect_tcp
    stream: anyio.abc.ByteStream = await anyio.connect_tcp(
  File "C:\Users\M9X\AppData\Local\Programs\Python\Python39\lib\site-packages\anyio\_core\_sockets.py", line 222, in connect_tcp
    raise OSError("All connection attempts failed") from cause
OSError: All connection attempts failed

The above exception was the direct cause of the following exception:

Traceback (most recent call last):
  File "C:\Users\M9X\AppData\Local\Programs\Python\Python39\lib\site-packages\httpx\_transports\default.py", line 60, in map_httpcore_exceptions
    yield
  File "C:\Users\M9X\AppData\Local\Programs\Python\Python39\lib\site-packages\httpx\_transports\default.py", line 353, in handle_async_request
    resp = await self._pool.handle_async_request(req)
  File "C:\Users\M9X\AppData\Local\Programs\Python\Python39\lib\site-packages\httpcore\_async\connection_pool.py", line 256, in handle_async_request
    raise exc
  File "C:\Users\M9X\AppData\Local\Programs\Python\Python39\lib\site-packages\httpcore\_async\connection_pool.py", line 240, in handle_async_request
    response = await connection.handle_async_request(request)
  File "C:\Users\M9X\AppData\Local\Programs\Python\Python39\lib\site-packages\httpcore\_async\connection.py", line 86, in handle_async_request
    raise exc
  File "C:\Users\M9X\AppData\Local\Programs\Python\Python39\lib\site-packages\httpcore\_async\connection.py", line 63, in handle_async_request
    stream = await self._connect(request)
  File "C:\Users\M9X\AppData\Local\Programs\Python\Python39\lib\site-packages\httpcore\_async\connection.py", line 111, in _connect
    stream = await self._network_backend.connect_tcp(**kwargs)
  File "C:\Users\M9X\AppData\Local\Programs\Python\Python39\lib\site-packages\httpcore\backends\auto.py", line 29, in connect_tcp
    return await self._backend.connect_tcp(
  File "C:\Users\M9X\AppData\Local\Programs\Python\Python39\lib\site-packages\httpcore\backends\asyncio.py", line 111, in connect_tcp
    stream: anyio.abc.ByteStream = await anyio.connect_tcp(
  File "C:\Users\M9X\AppData\Local\Programs\Python\Python39\lib\contextlib.py", line 135, in __exit__
    self.gen.throw(type, value, traceback)
  File "C:\Users\M9X\AppData\Local\Programs\Python\Python39\lib\site-packages\httpcore\_exceptions.py", line 14, in map_exceptions
    raise to_exc(exc) from exc
httpcore.ConnectError: All connection attempts failed

The above exception was the direct cause of the following exception:

Traceback (most recent call last):
  File "C:\Users\M9X\AppData\Local\Programs\Python\Python39\lib\site-packages\telegram\request\_httpxrequest.py", line 216, in do_request
    res = await self._client.request(
  File "C:\Users\M9X\AppData\Local\Programs\Python\Python39\lib\site-packages\httpx\_client.py", line 1530, in request
    return await self.send(request, auth=auth, follow_redirects=follow_redirects)
  File "C:\Users\M9X\AppData\Local\Programs\Python\Python39\lib\site-packages\httpx\_client.py", line 1617, in send
    response = await self._send_handling_auth(
  File "C:\Users\M9X\AppData\Local\Programs\Python\Python39\lib\site-packages\httpx\_client.py", line 1645, in _send_handling_auth
    response = await self._send_handling_redirects(
  File "C:\Users\M9X\AppData\Local\Programs\Python\Python39\lib\site-packages\httpx\_client.py", line 1682, in _send_handling_redirects
    response = await self._send_single_request(request)
  File "C:\Users\M9X\AppData\Local\Programs\Python\Python39\lib\site-packages\httpx\_client.py", line 1719, in _send_single_request
    response = await transport.handle_async_request(request)
  File "C:\Users\M9X\AppData\Local\Programs\Python\Python39\lib\site-packages\httpx\_transports\default.py", line 353, in handle_async_request
    resp = await self._pool.handle_async_request(req)
  File "C:\Users\M9X\AppData\Local\Programs\Python\Python39\lib\contextlib.py", line 135, in __exit__
    self.gen.throw(type, value, traceback)
  File "C:\Users\M9X\AppData\Local\Programs\Python\Python39\lib\site-packages\httpx\_transports\default.py", line 77, in map_httpcore_exceptions
    raise mapped_exc(message) from exc
httpx.ConnectError: All connection attempts failed

The above exception was the direct cause of the following exception:

Traceback (most recent call last):
  File "C:\Users\M9X\AppData\Local\Programs\Python\Python39\lib\site-packages\telegram\ext\_updater.py", line 607, in _network_loop_retry
    if not await action_cb():
  File "C:\Users\M9X\AppData\Local\Programs\Python\Python39\lib\site-packages\telegram\ext\_updater.py", line 335, in polling_action_cb
    raise exc
  File "C:\Users\M9X\AppData\Local\Programs\Python\Python39\lib\site-packages\telegram\ext\_updater.py", line 320, in polling_action_cb
    updates = await self.bot.get_updates(
  File "C:\Users\M9X\AppData\Local\Programs\Python\Python39\lib\site-packages\telegram\ext\_extbot.py", line 543, in get_updates
    updates = await super().get_updates(
  File "C:\Users\M9X\AppData\Local\Programs\Python\Python39\lib\site-packages\telegram\_bot.py", line 381, in decorator
    result = await func(self, *args, **kwargs)  # skipcq: PYL-E1102
  File "C:\Users\M9X\AppData\Local\Programs\Python\Python39\lib\site-packages\telegram\_bot.py", line 3661, in get_updates
    await self._post(
  File "C:\Users\M9X\AppData\Local\Programs\Python\Python39\lib\site-packages\telegram\_bot.py", line 469, in _post
    return await self._do_post(
  File "C:\Users\M9X\AppData\Local\Programs\Python\Python39\lib\site-packages\telegram\ext\_extbot.py", line 325, in _do_post
    return await super()._do_post(
  File "C:\Users\M9X\AppData\Local\Programs\Python\Python39\lib\site-packages\telegram\_bot.py", line 497, in _do_post
    return await request.post(
  File "C:\Users\M9X\AppData\Local\Programs\Python\Python39\lib\site-packages\telegram\request\_baserequest.py", line 168, in post
    result = await self._request_wrapper(
  File "C:\Users\M9X\AppData\Local\Programs\Python\Python39\lib\site-packages\telegram\request\_baserequest.py", line 291, in _request_wrapper
    raise exc
  File "C:\Users\M9X\AppData\Local\Programs\Python\Python39\lib\site-packages\telegram\request\_baserequest.py", line 277, in _request_wrapper
    code, payload = await self.do_request(
  File "C:\Users\M9X\AppData\Local\Programs\Python\Python39\lib\site-packages\telegram\request\_httpxrequest.py", line 240, in do_request
    raise NetworkError(f"httpx.{err.__class__.__name__}: {err}") from err
telegram.error.NetworkError: httpx.ConnectError: All connection attempts failed
2023-06-16 07:52:01,896 - INFO - Application is stopping. This might take a moment. - msg
2023-06-16 07:52:01,896 - INFO - Application.stop() complete - msg
2023-06-16 07:53:01,157 - INFO - Start bot - msg
2023-06-16 07:53:02,157 - INFO - Application started - msg
2023-06-16 07:53:47,336 - ERROR - No error handlers are registered, logging exception. - msg
Traceback (most recent call last):
  File "C:\Users\M9X\AppData\Local\Programs\Python\Python39\lib\site-packages\urllib3\connection.py", line 200, in _new_conn
    sock = connection.create_connection(
  File "C:\Users\M9X\AppData\Local\Programs\Python\Python39\lib\site-packages\urllib3\util\connection.py", line 85, in create_connection
    raise err
  File "C:\Users\M9X\AppData\Local\Programs\Python\Python39\lib\site-packages\urllib3\util\connection.py", line 73, in create_connection
    sock.connect(sa)
TimeoutError: [WinError 10060] Попытка установить соединение была безуспешной, т.к. от другого компьютера за требуемое время не получен нужный отклик, или было разорвано уже установленное соединение из-за неверного отклика уже подключенного компьютера

The above exception was the direct cause of the following exception:

Traceback (most recent call last):
  File "C:\Users\M9X\AppData\Local\Programs\Python\Python39\lib\site-packages\urllib3\connectionpool.py", line 790, in urlopen
    response = self._make_request(
  File "C:\Users\M9X\AppData\Local\Programs\Python\Python39\lib\site-packages\urllib3\connectionpool.py", line 491, in _make_request
    raise new_e
  File "C:\Users\M9X\AppData\Local\Programs\Python\Python39\lib\site-packages\urllib3\connectionpool.py", line 467, in _make_request
    self._validate_conn(conn)
  File "C:\Users\M9X\AppData\Local\Programs\Python\Python39\lib\site-packages\urllib3\connectionpool.py", line 1092, in _validate_conn
    conn.connect()
  File "C:\Users\M9X\AppData\Local\Programs\Python\Python39\lib\site-packages\urllib3\connection.py", line 604, in connect
    self.sock = sock = self._new_conn()
  File "C:\Users\M9X\AppData\Local\Programs\Python\Python39\lib\site-packages\urllib3\connection.py", line 215, in _new_conn
    raise NewConnectionError(
urllib3.exceptions.NewConnectionError: <urllib3.connection.HTTPSConnection object at 0x000002096DB8AA30>: Failed to establish a new connection: [WinError 10060] Попытка установить соединение была безуспешной, т.к. от другого компьютера за требуемое время не получен нужный отклик, или было разорвано уже установленное соединение из-за неверного отклика уже подключенного компьютера

The above exception was the direct cause of the following exception:

Traceback (most recent call last):
  File "C:\Users\M9X\AppData\Local\Programs\Python\Python39\lib\site-packages\requests\adapters.py", line 486, in send
    resp = conn.urlopen(
  File "C:\Users\M9X\AppData\Local\Programs\Python\Python39\lib\site-packages\urllib3\connectionpool.py", line 844, in urlopen
    retries = retries.increment(
  File "C:\Users\M9X\AppData\Local\Programs\Python\Python39\lib\site-packages\urllib3\util\retry.py", line 515, in increment
    raise MaxRetryError(_pool, url, reason) from reason  # type: ignore[arg-type]
urllib3.exceptions.MaxRetryError: HTTPSConnectionPool(host='teletype.in', port=443): Max retries exceeded with url: /@haskie1337 (Caused by NewConnectionError('<urllib3.connection.HTTPSConnection object at 0x000002096DB8AA30>: Failed to establish a new connection: [WinError 10060] Попытка установить соединение была безуспешной, т.к. от другого компьютера за требуемое время не получен нужный отклик, или было разорвано уже установленное соединение из-за неверного отклика уже подключенного компьютера'))

During handling of the above exception, another exception occurred:

Traceback (most recent call last):
  File "C:\Users\M9X\AppData\Local\Programs\Python\Python39\lib\site-packages\telegram\ext\_application.py", line 1124, in process_update
    await coroutine
  File "C:\Users\M9X\AppData\Local\Programs\Python\Python39\lib\site-packages\telegram\ext\_handler.py", line 141, in handle_update
    return await self.callback(update, context)
  File "C:\Users\M9X\Desktop\4_Сем\ИС_Python\Sem4_is\9_Async_ChatBots\Task_6.py", line 106, in lastwork
    r = requests.get('https://teletype.in/@haskie1337')
  File "C:\Users\M9X\AppData\Local\Programs\Python\Python39\lib\site-packages\requests\api.py", line 73, in get
    return request("get", url, params=params, **kwargs)
  File "C:\Users\M9X\AppData\Local\Programs\Python\Python39\lib\site-packages\requests\api.py", line 59, in request
    return session.request(method=method, url=url, **kwargs)
  File "C:\Users\M9X\AppData\Local\Programs\Python\Python39\lib\site-packages\requests\sessions.py", line 589, in request
    resp = self.send(prep, **send_kwargs)
  File "C:\Users\M9X\AppData\Local\Programs\Python\Python39\lib\site-packages\requests\sessions.py", line 703, in send
    r = adapter.send(request, **kwargs)
  File "C:\Users\M9X\AppData\Local\Programs\Python\Python39\lib\site-packages\requests\adapters.py", line 519, in send
    raise ConnectionError(e, request=request)
requests.exceptions.ConnectionError: HTTPSConnectionPool(host='teletype.in', port=443): Max retries exceeded with url: /@haskie1337 (Caused by NewConnectionError('<urllib3.connection.HTTPSConnection object at 0x000002096DB8AA30>: Failed to establish a new connection: [WinError 10060] Попытка установить соединение была безуспешной, т.к. от другого компьютера за требуемое время не получен нужный отклик, или было разорвано уже установленное соединение из-за неверного отклика уже подключенного компьютера'))
2023-06-16 07:54:18,390 - ERROR - No error handlers are registered, logging exception. - msg
Traceback (most recent call last):
  File "C:\Users\M9X\AppData\Local\Programs\Python\Python39\lib\site-packages\urllib3\connection.py", line 200, in _new_conn
    sock = connection.create_connection(
  File "C:\Users\M9X\AppData\Local\Programs\Python\Python39\lib\site-packages\urllib3\util\connection.py", line 85, in create_connection
    raise err
  File "C:\Users\M9X\AppData\Local\Programs\Python\Python39\lib\site-packages\urllib3\util\connection.py", line 73, in create_connection
    sock.connect(sa)
TimeoutError: [WinError 10060] Попытка установить соединение была безуспешной, т.к. от другого компьютера за требуемое время не получен нужный отклик, или было разорвано уже установленное соединение из-за неверного отклика уже подключенного компьютера

The above exception was the direct cause of the following exception:

Traceback (most recent call last):
  File "C:\Users\M9X\AppData\Local\Programs\Python\Python39\lib\site-packages\urllib3\connectionpool.py", line 790, in urlopen
    response = self._make_request(
  File "C:\Users\M9X\AppData\Local\Programs\Python\Python39\lib\site-packages\urllib3\connectionpool.py", line 491, in _make_request
    raise new_e
  File "C:\Users\M9X\AppData\Local\Programs\Python\Python39\lib\site-packages\urllib3\connectionpool.py", line 467, in _make_request
    self._validate_conn(conn)
  File "C:\Users\M9X\AppData\Local\Programs\Python\Python39\lib\site-packages\urllib3\connectionpool.py", line 1092, in _validate_conn
    conn.connect()
  File "C:\Users\M9X\AppData\Local\Programs\Python\Python39\lib\site-packages\urllib3\connection.py", line 604, in connect
    self.sock = sock = self._new_conn()
  File "C:\Users\M9X\AppData\Local\Programs\Python\Python39\lib\site-packages\urllib3\connection.py", line 215, in _new_conn
    raise NewConnectionError(
urllib3.exceptions.NewConnectionError: <urllib3.connection.HTTPSConnection object at 0x000002096C8C13A0>: Failed to establish a new connection: [WinError 10060] Попытка установить соединение была безуспешной, т.к. от другого компьютера за требуемое время не получен нужный отклик, или было разорвано уже установленное соединение из-за неверного отклика уже подключенного компьютера

The above exception was the direct cause of the following exception:

Traceback (most recent call last):
  File "C:\Users\M9X\AppData\Local\Programs\Python\Python39\lib\site-packages\requests\adapters.py", line 486, in send
    resp = conn.urlopen(
  File "C:\Users\M9X\AppData\Local\Programs\Python\Python39\lib\site-packages\urllib3\connectionpool.py", line 844, in urlopen
    retries = retries.increment(
  File "C:\Users\M9X\AppData\Local\Programs\Python\Python39\lib\site-packages\urllib3\util\retry.py", line 515, in increment
    raise MaxRetryError(_pool, url, reason) from reason  # type: ignore[arg-type]
urllib3.exceptions.MaxRetryError: HTTPSConnectionPool(host='teletype.in', port=443): Max retries exceeded with url: /@haskie1337 (Caused by NewConnectionError('<urllib3.connection.HTTPSConnection object at 0x000002096C8C13A0>: Failed to establish a new connection: [WinError 10060] Попытка установить соединение была безуспешной, т.к. от другого компьютера за требуемое время не получен нужный отклик, или было разорвано уже установленное соединение из-за неверного отклика уже подключенного компьютера'))

During handling of the above exception, another exception occurred:

Traceback (most recent call last):
  File "C:\Users\M9X\AppData\Local\Programs\Python\Python39\lib\site-packages\telegram\ext\_application.py", line 1124, in process_update
    await coroutine
  File "C:\Users\M9X\AppData\Local\Programs\Python\Python39\lib\site-packages\telegram\ext\_handler.py", line 141, in handle_update
    return await self.callback(update, context)
  File "C:\Users\M9X\Desktop\4_Сем\ИС_Python\Sem4_is\9_Async_ChatBots\Task_6.py", line 106, in lastwork
    r = requests.get('https://teletype.in/@haskie1337')
  File "C:\Users\M9X\AppData\Local\Programs\Python\Python39\lib\site-packages\requests\api.py", line 73, in get
    return request("get", url, params=params, **kwargs)
  File "C:\Users\M9X\AppData\Local\Programs\Python\Python39\lib\site-packages\requests\api.py", line 59, in request
    return session.request(method=method, url=url, **kwargs)
  File "C:\Users\M9X\AppData\Local\Programs\Python\Python39\lib\site-packages\requests\sessions.py", line 589, in request
    resp = self.send(prep, **send_kwargs)
  File "C:\Users\M9X\AppData\Local\Programs\Python\Python39\lib\site-packages\requests\sessions.py", line 703, in send
    r = adapter.send(request, **kwargs)
  File "C:\Users\M9X\AppData\Local\Programs\Python\Python39\lib\site-packages\requests\adapters.py", line 519, in send
    raise ConnectionError(e, request=request)
requests.exceptions.ConnectionError: HTTPSConnectionPool(host='teletype.in', port=443): Max retries exceeded with url: /@haskie1337 (Caused by NewConnectionError('<urllib3.connection.HTTPSConnection object at 0x000002096C8C13A0>: Failed to establish a new connection: [WinError 10060] Попытка установить соединение была безуспешной, т.к. от другого компьютера за требуемое время не получен нужный отклик, или было разорвано уже установленное соединение из-за неверного отклика уже подключенного компьютера'))
2023-06-16 07:56:30,602 - INFO - Application is stopping. This might take a moment. - msg
2023-06-16 07:56:30,602 - INFO - Application.stop() complete - msg
